'use strict';
/*------------------------------------------------------------------------------
Full description at: https://github.com/HackYourFuture/Assignments/tree/main/3-UsingAPIs/Week1#exercise-3-roll-a-die

- Run the unmodified program and confirm that problem described occurs.
- Refactor the `rollDie()` function from callback-based to returning a
  promise.
- Change the calls to `callback()` to calls to `resolve()` and `reject()`.
- Refactor the code that call `rollDie()` to use the promise it returns.
- Does the problem described above still occur? If not, what would be your
  explanation? Add your answer as a comment to be bottom of the file.
------------------------------------------------------------------------------*/

function rollDie() {
  return new Promise((resolve, reject) => {
    const randomRollsToDo = Math.floor(Math.random() * 8) + 3;
    console.log(`Die scheduled for ${randomRollsToDo} rolls...`);

    const rollOnce = (roll) => {
      const value = Math.floor(Math.random() * 6) + 1;
      console.log(`Die value is now: ${value}`);

      if (roll > 6) {
        reject(new Error('Oops... Die rolled off the table.'));
        return;
      }

      if (roll === randomRollsToDo) {
        resolve(value);
        return;
      }

      if (roll < randomRollsToDo) {
        setTimeout(() => rollOnce(roll + 1), 500);
      }
    };

    rollOnce(1);
  });
}

function main() {
  rollDie()
    .then((value) => {
      console.log(`Success! Die settled on ${value}.`);
    })
    .catch((error) => {
      console.log(error.message);
    });
}

// ! Do not change or remove the code below
if (process.env.NODE_ENV !== 'test') {
  main();
}
module.exports = rollDie;

// !Explanation:
// No, the problem no longer occurs after refactoring rollDie() to return a promise.
// With promises, when one die roll fails, the entire promise chain is rejected,
// stopping the other die rolls from continuing. This centralized control flow
// is the key difference from the previous callback-based implementation.
